[28Sep2022 00:21:07 INFO [django.utils.autoreload:637] Watching for file changes with StatReloader
[28Sep2022 00:21:10 INFO [django.server:161] "GET / HTTP/1.1" 200 23411
[28Sep2022 00:21:10 INFO [django.server:161] "GET /static/bootstrap/vendor/fontawesome-free/css/all.min.css HTTP/1.1" 304 0
[28Sep2022 00:21:10 INFO [django.server:161] "GET /static/bootstrap/css/sb-admin-2.min.css HTTP/1.1" 304 0
[28Sep2022 00:21:10 INFO [django.server:161] "GET /static/bootstrap/vendor/jquery/jquery.min.js HTTP/1.1" 304 0
[28Sep2022 00:21:10 INFO [django.server:161] "GET /static/bootstrap/vendor/bootstrap/js/bootstrap.bundle.min.js HTTP/1.1" 304 0
[28Sep2022 00:21:10 INFO [django.server:161] "GET /static/bootstrap/vendor/jquery-easing/jquery.easing.min.js HTTP/1.1" 304 0
[28Sep2022 00:21:10 INFO [django.server:161] "GET /static/bootstrap/vendor/chart.js/Chart.min.js HTTP/1.1" 304 0
[28Sep2022 00:21:10 INFO [django.server:161] "GET /static/bootstrap/js/sb-admin-2.js HTTP/1.1" 304 0
[28Sep2022 00:21:10 INFO [django.server:161] "GET /static/bootstrap/js/demo/chart-pie-demo.js HTTP/1.1" 304 0
[28Sep2022 00:21:10 INFO [django.server:161] "GET /static/bootstrap/js/demo/chart-area-demo.js HTTP/1.1" 304 0
[28Sep2022 00:21:10 INFO [django.server:161] "GET /static/bootstrap/img/logo_blue.png HTTP/1.1" 304 0
[28Sep2022 00:21:10 INFO [django.server:161] "GET /static/bootstrap/img/undraw_profile.svg HTTP/1.1" 304 0
[28Sep2022 00:21:10 INFO [django.server:161] "GET /static/bootstrap/vendor/fontawesome-free/webfonts/fa-solid-900.woff2 HTTP/1.1" 304 0
[28Sep2022 00:21:10 INFO [django.server:161] "GET /static/bootstrap/img/by.jpg HTTP/1.1" 304 0
[28Sep2022 00:21:13 INFO [django.server:161] "GET /static/bootstrap/vendor/bootstrap/js/bootstrap.bundle.min.js.map HTTP/1.1" 200 316181
[28Sep2022 00:21:17 INFO [django.server:161] "GET /fast_search/ HTTP/1.1" 200 17435
[28Sep2022 00:21:17 INFO [django.server:161] "GET /static/bootstrap/img/icon_image.png HTTP/1.1" 304 0
[28Sep2022 00:21:17 INFO [django.server:161] "GET /static/bootstrap/img/icon_keyword.png HTTP/1.1" 304 0
[28Sep2022 00:21:17 INFO [django.server:161] "GET /static/bootstrap/vendor/bootstrap/js/bootstrap.bundle.min.js.map HTTP/1.1" 200 316181
[28Sep2022 00:21:18 INFO [django.server:161] "GET /fast_search/keyword/ HTTP/1.1" 200 19305
[28Sep2022 00:21:18 INFO [django.server:161] "GET /static/bootstrap/vendor/bootstrap/js/bootstrap.bundle.min.js.map HTTP/1.1" 200 316181
[28Sep2022 00:21:25 INFO [django.server:161] "GET /fast_search/keyword/key_result/?insert_category=%EA%B0%80%EB%B0%A9&insert_color=%EA%B2%80%EC%A0%95&insert_date=2022-09-01 HTTP/1.1" 200 25326
[28Sep2022 00:21:25 INFO [django.server:161] "GET /static/acha_money/css/base.css HTTP/1.1" 304 0
[28Sep2022 00:21:25 INFO [django.server:161] "GET /static/bootstrap/img/no_image.png HTTP/1.1" 200 40047
[28Sep2022 00:21:26 INFO [django.server:161] "GET /static/bootstrap/vendor/bootstrap/js/bootstrap.bundle.min.js.map HTTP/1.1" 200 316181
[28Sep2022 00:42:44 INFO [django.utils.autoreload:637] Watching for file changes with StatReloader
[28Sep2022 00:42:55 INFO [django.server:161] "GET /fast_search/image/ HTTP/1.1" 200 21430
[28Sep2022 00:42:56 INFO [django.server:161] "GET /static/bootstrap/vendor/bootstrap/js/bootstrap.bundle.min.js.map HTTP/1.1" 200 316181
[28Sep2022 00:43:03 ERROR [django.request:230] Internal Server Error: /fast_search/image/upload/
Traceback (most recent call last):
  File "/Users/jihyun/opt/anaconda3/envs/achacha/lib/python3.6/site-packages/urllib3/connection.py", line 175, in _new_conn
    (self._dns_host, self.port), self.timeout, **extra_kw
  File "/Users/jihyun/opt/anaconda3/envs/achacha/lib/python3.6/site-packages/urllib3/util/connection.py", line 95, in create_connection
    raise err
  File "/Users/jihyun/opt/anaconda3/envs/achacha/lib/python3.6/site-packages/urllib3/util/connection.py", line 85, in create_connection
    sock.connect(sa)
ConnectionRefusedError: [Errno 61] Connection refused

During handling of the above exception, another exception occurred:

Traceback (most recent call last):
  File "/Users/jihyun/opt/anaconda3/envs/achacha/lib/python3.6/site-packages/urllib3/connectionpool.py", line 710, in urlopen
    chunked=chunked,
  File "/Users/jihyun/opt/anaconda3/envs/achacha/lib/python3.6/site-packages/urllib3/connectionpool.py", line 398, in _make_request
    conn.request(method, url, **httplib_request_kw)
  File "/Users/jihyun/opt/anaconda3/envs/achacha/lib/python3.6/site-packages/urllib3/connection.py", line 239, in request
    super(HTTPConnection, self).request(method, url, body=body, headers=headers)
  File "/Users/jihyun/opt/anaconda3/envs/achacha/lib/python3.6/http/client.py", line 1254, in request
    self._send_request(method, url, body, headers, encode_chunked)
  File "/Users/jihyun/opt/anaconda3/envs/achacha/lib/python3.6/http/client.py", line 1300, in _send_request
    self.endheaders(body, encode_chunked=encode_chunked)
  File "/Users/jihyun/opt/anaconda3/envs/achacha/lib/python3.6/http/client.py", line 1249, in endheaders
    self._send_output(message_body, encode_chunked=encode_chunked)
  File "/Users/jihyun/opt/anaconda3/envs/achacha/lib/python3.6/http/client.py", line 1036, in _send_output
    self.send(msg)
  File "/Users/jihyun/opt/anaconda3/envs/achacha/lib/python3.6/http/client.py", line 974, in send
    self.connect()
  File "/Users/jihyun/opt/anaconda3/envs/achacha/lib/python3.6/site-packages/urllib3/connection.py", line 205, in connect
    conn = self._new_conn()
  File "/Users/jihyun/opt/anaconda3/envs/achacha/lib/python3.6/site-packages/urllib3/connection.py", line 187, in _new_conn
    self, "Failed to establish a new connection: %s" % e
urllib3.exceptions.NewConnectionError: <urllib3.connection.HTTPConnection object at 0x7fb8b359a7f0>: Failed to establish a new connection: [Errno 61] Connection refused

During handling of the above exception, another exception occurred:

Traceback (most recent call last):
  File "/Users/jihyun/opt/anaconda3/envs/achacha/lib/python3.6/site-packages/requests/adapters.py", line 450, in send
    timeout=timeout
  File "/Users/jihyun/opt/anaconda3/envs/achacha/lib/python3.6/site-packages/urllib3/connectionpool.py", line 788, in urlopen
    method, url, error=e, _pool=self, _stacktrace=sys.exc_info()[2]
  File "/Users/jihyun/opt/anaconda3/envs/achacha/lib/python3.6/site-packages/urllib3/util/retry.py", line 592, in increment
    raise MaxRetryError(_pool, url, error or ResponseError(cause))
urllib3.exceptions.MaxRetryError: HTTPConnectionPool(host='localhost', port=5001): Max retries exceeded with url: / (Caused by NewConnectionError('<urllib3.connection.HTTPConnection object at 0x7fb8b359a7f0>: Failed to establish a new connection: [Errno 61] Connection refused',))

During handling of the above exception, another exception occurred:

Traceback (most recent call last):
  File "/Users/jihyun/opt/anaconda3/envs/achacha/lib/python3.6/site-packages/django/core/handlers/exception.py", line 47, in inner
    response = get_response(request)
  File "/Users/jihyun/opt/anaconda3/envs/achacha/lib/python3.6/site-packages/django/core/handlers/base.py", line 181, in _get_response
    response = wrapped_callback(request, *callback_args, **callback_kwargs)
  File "/Users/jihyun/PJT_ACHACHA/ACHACHA_PROJECT/achacha_django/fast_search/views.py", line 78, in uploaded_image
    response = requests.post('http://localhost:5001/', data=data)
  File "/Users/jihyun/opt/anaconda3/envs/achacha/lib/python3.6/site-packages/requests/api.py", line 117, in post
    return request('post', url, data=data, json=json, **kwargs)
  File "/Users/jihyun/opt/anaconda3/envs/achacha/lib/python3.6/site-packages/requests/api.py", line 61, in request
    return session.request(method=method, url=url, **kwargs)
  File "/Users/jihyun/opt/anaconda3/envs/achacha/lib/python3.6/site-packages/requests/sessions.py", line 529, in request
    resp = self.send(prep, **send_kwargs)
  File "/Users/jihyun/opt/anaconda3/envs/achacha/lib/python3.6/site-packages/requests/sessions.py", line 645, in send
    r = adapter.send(request, **kwargs)
  File "/Users/jihyun/opt/anaconda3/envs/achacha/lib/python3.6/site-packages/requests/adapters.py", line 519, in send
    raise ConnectionError(e, request=request)
requests.exceptions.ConnectionError: HTTPConnectionPool(host='localhost', port=5001): Max retries exceeded with url: / (Caused by NewConnectionError('<urllib3.connection.HTTPConnection object at 0x7fb8b359a7f0>: Failed to establish a new connection: [Errno 61] Connection refused',))
[28Sep2022 00:43:03 ERROR [django.server:161] "POST /fast_search/image/upload/ HTTP/1.1" 500 243173
[28Sep2022 00:44:48 INFO [django.server:161] "GET / HTTP/1.1" 200 23411
[28Sep2022 00:44:53 INFO [django.server:161] "GET /fast_search/image/ HTTP/1.1" 200 21430
[28Sep2022 00:44:53 INFO [django.server:161] "GET /static/bootstrap/vendor/bootstrap/js/bootstrap.bundle.min.js.map HTTP/1.1" 200 316181
[28Sep2022 00:46:00 INFO [django.utils.autoreload:637] Watching for file changes with StatReloader
[28Sep2022 00:46:05 INFO [django.server:161] "GET /fast_search/image/ HTTP/1.1" 200 21430
[28Sep2022 00:46:05 INFO [django.server:161] "GET /static/bootstrap/vendor/bootstrap/js/bootstrap.bundle.min.js.map HTTP/1.1" 200 316181
[28Sep2022 00:53:59 INFO [django.utils.autoreload:637] Watching for file changes with StatReloader
[28Sep2022 00:54:03 INFO [django.server:161] "GET /fast_search/image/ HTTP/1.1" 200 21430
[28Sep2022 00:54:03 INFO [django.server:161] "GET /static/bootstrap/vendor/bootstrap/js/bootstrap.bundle.min.js.map HTTP/1.1" 200 316181
[28Sep2022 00:54:12 ERROR [django.request:230] Internal Server Error: /fast_search/image/upload/
Traceback (most recent call last):
  File "/Users/jihyun/opt/anaconda3/envs/achacha/lib/python3.6/site-packages/django/db/backends/utils.py", line 84, in _execute
    return self.cursor.execute(sql, params)
  File "/Users/jihyun/opt/anaconda3/envs/achacha/lib/python3.6/site-packages/django/db/backends/mysql/base.py", line 73, in execute
    return self.cursor.execute(query, args)
  File "/Users/jihyun/opt/anaconda3/envs/achacha/lib/python3.6/site-packages/pymysql/cursors.py", line 148, in execute
    result = self._query(query)
  File "/Users/jihyun/opt/anaconda3/envs/achacha/lib/python3.6/site-packages/pymysql/cursors.py", line 310, in _query
    conn.query(q)
  File "/Users/jihyun/opt/anaconda3/envs/achacha/lib/python3.6/site-packages/pymysql/connections.py", line 548, in query
    self._affected_rows = self._read_query_result(unbuffered=unbuffered)
  File "/Users/jihyun/opt/anaconda3/envs/achacha/lib/python3.6/site-packages/pymysql/connections.py", line 775, in _read_query_result
    result.read()
  File "/Users/jihyun/opt/anaconda3/envs/achacha/lib/python3.6/site-packages/pymysql/connections.py", line 1156, in read
    first_packet = self.connection._read_packet()
  File "/Users/jihyun/opt/anaconda3/envs/achacha/lib/python3.6/site-packages/pymysql/connections.py", line 725, in _read_packet
    packet.raise_for_error()
  File "/Users/jihyun/opt/anaconda3/envs/achacha/lib/python3.6/site-packages/pymysql/protocol.py", line 221, in raise_for_error
    err.raise_mysql_exception(self._data)
  File "/Users/jihyun/opt/anaconda3/envs/achacha/lib/python3.6/site-packages/pymysql/err.py", line 143, in raise_mysql_exception
    raise errorclass(errno, errval)
pymysql.err.OperationalError: (1222, 'The used SELECT statements have a different number of columns')

The above exception was the direct cause of the following exception:

Traceback (most recent call last):
  File "/Users/jihyun/opt/anaconda3/envs/achacha/lib/python3.6/site-packages/django/core/handlers/exception.py", line 47, in inner
    response = get_response(request)
  File "/Users/jihyun/opt/anaconda3/envs/achacha/lib/python3.6/site-packages/django/core/handlers/base.py", line 181, in _get_response
    response = wrapped_callback(request, *callback_args, **callback_kwargs)
  File "/Users/jihyun/PJT_ACHACHA/ACHACHA_PROJECT/achacha_django/fast_search/views.py", line 110, in uploaded_image
    print(a)
  File "/Users/jihyun/opt/anaconda3/envs/achacha/lib/python3.6/site-packages/django/db/models/query.py", line 256, in __repr__
    data = list(self[:REPR_OUTPUT_SIZE + 1])
  File "/Users/jihyun/opt/anaconda3/envs/achacha/lib/python3.6/site-packages/django/db/models/query.py", line 280, in __iter__
    self._fetch_all()
  File "/Users/jihyun/opt/anaconda3/envs/achacha/lib/python3.6/site-packages/django/db/models/query.py", line 1324, in _fetch_all
    self._result_cache = list(self._iterable_class(self))
  File "/Users/jihyun/opt/anaconda3/envs/achacha/lib/python3.6/site-packages/django/db/models/query.py", line 51, in __iter__
    results = compiler.execute_sql(chunked_fetch=self.chunked_fetch, chunk_size=self.chunk_size)
  File "/Users/jihyun/opt/anaconda3/envs/achacha/lib/python3.6/site-packages/django/db/models/sql/compiler.py", line 1175, in execute_sql
    cursor.execute(sql, params)
  File "/Users/jihyun/opt/anaconda3/envs/achacha/lib/python3.6/site-packages/django/db/backends/utils.py", line 98, in execute
    return super().execute(sql, params)
  File "/Users/jihyun/opt/anaconda3/envs/achacha/lib/python3.6/site-packages/django/db/backends/utils.py", line 66, in execute
    return self._execute_with_wrappers(sql, params, many=False, executor=self._execute)
  File "/Users/jihyun/opt/anaconda3/envs/achacha/lib/python3.6/site-packages/django/db/backends/utils.py", line 75, in _execute_with_wrappers
    return executor(sql, params, many, context)
  File "/Users/jihyun/opt/anaconda3/envs/achacha/lib/python3.6/site-packages/django/db/backends/utils.py", line 84, in _execute
    return self.cursor.execute(sql, params)
  File "/Users/jihyun/opt/anaconda3/envs/achacha/lib/python3.6/site-packages/django/db/utils.py", line 90, in __exit__
    raise dj_exc_value.with_traceback(traceback) from exc_value
  File "/Users/jihyun/opt/anaconda3/envs/achacha/lib/python3.6/site-packages/django/db/backends/utils.py", line 84, in _execute
    return self.cursor.execute(sql, params)
  File "/Users/jihyun/opt/anaconda3/envs/achacha/lib/python3.6/site-packages/django/db/backends/mysql/base.py", line 73, in execute
    return self.cursor.execute(query, args)
  File "/Users/jihyun/opt/anaconda3/envs/achacha/lib/python3.6/site-packages/pymysql/cursors.py", line 148, in execute
    result = self._query(query)
  File "/Users/jihyun/opt/anaconda3/envs/achacha/lib/python3.6/site-packages/pymysql/cursors.py", line 310, in _query
    conn.query(q)
  File "/Users/jihyun/opt/anaconda3/envs/achacha/lib/python3.6/site-packages/pymysql/connections.py", line 548, in query
    self._affected_rows = self._read_query_result(unbuffered=unbuffered)
  File "/Users/jihyun/opt/anaconda3/envs/achacha/lib/python3.6/site-packages/pymysql/connections.py", line 775, in _read_query_result
    result.read()
  File "/Users/jihyun/opt/anaconda3/envs/achacha/lib/python3.6/site-packages/pymysql/connections.py", line 1156, in read
    first_packet = self.connection._read_packet()
  File "/Users/jihyun/opt/anaconda3/envs/achacha/lib/python3.6/site-packages/pymysql/connections.py", line 725, in _read_packet
    packet.raise_for_error()
  File "/Users/jihyun/opt/anaconda3/envs/achacha/lib/python3.6/site-packages/pymysql/protocol.py", line 221, in raise_for_error
    err.raise_mysql_exception(self._data)
  File "/Users/jihyun/opt/anaconda3/envs/achacha/lib/python3.6/site-packages/pymysql/err.py", line 143, in raise_mysql_exception
    raise errorclass(errno, errval)
django.db.utils.OperationalError: (1222, 'The used SELECT statements have a different number of columns')
[28Sep2022 00:54:12 ERROR [django.server:161] "POST /fast_search/image/upload/ HTTP/1.1" 500 222138
[28Sep2022 00:55:38 INFO [django.utils.autoreload:251] /Users/jihyun/PJT_ACHACHA/ACHACHA_PROJECT/achacha_django/fast_search/views.py changed, reloading.
[28Sep2022 00:55:39 INFO [django.utils.autoreload:637] Watching for file changes with StatReloader
[28Sep2022 00:55:42 INFO [django.server:161] "GET /fast_search/image/ HTTP/1.1" 200 21430
[28Sep2022 00:55:43 INFO [django.server:161] "GET /static/bootstrap/vendor/bootstrap/js/bootstrap.bundle.min.js.map HTTP/1.1" 200 316181
[28Sep2022 00:55:57 ERROR [django.request:230] Internal Server Error: /fast_search/image/upload/
Traceback (most recent call last):
  File "/Users/jihyun/opt/anaconda3/envs/achacha/lib/python3.6/site-packages/django/core/handlers/exception.py", line 47, in inner
    response = get_response(request)
  File "/Users/jihyun/opt/anaconda3/envs/achacha/lib/python3.6/site-packages/django/core/handlers/base.py", line 181, in _get_response
    response = wrapped_callback(request, *callback_args, **callback_kwargs)
  File "/Users/jihyun/PJT_ACHACHA/ACHACHA_PROJECT/achacha_django/fast_search/views.py", line 111, in uploaded_image
    b = list(chain(image2, lost_item_data2))
NameError: name 'chain' is not defined
[28Sep2022 00:55:57 ERROR [django.server:161] "POST /fast_search/image/upload/ HTTP/1.1" 500 84454
[28Sep2022 00:56:22 INFO [django.utils.autoreload:251] /Users/jihyun/PJT_ACHACHA/ACHACHA_PROJECT/achacha_django/fast_search/views.py changed, reloading.
[28Sep2022 00:56:24 INFO [django.utils.autoreload:637] Watching for file changes with StatReloader
[28Sep2022 00:56:32 INFO [django.server:161] "GET /fast_search/image/ HTTP/1.1" 200 21430
[28Sep2022 00:56:32 INFO [django.server:161] "GET /static/bootstrap/vendor/bootstrap/js/bootstrap.bundle.min.js.map HTTP/1.1" 200 316181
[28Sep2022 00:57:02 INFO [django.utils.autoreload:251] /Users/jihyun/PJT_ACHACHA/ACHACHA_PROJECT/achacha_django/fast_search/views.py changed, reloading.
[28Sep2022 00:57:04 INFO [django.utils.autoreload:637] Watching for file changes with StatReloader
[28Sep2022 00:57:13 ERROR [django.request:230] Internal Server Error: /fast_search/image/upload/
Traceback (most recent call last):
  File "/Users/jihyun/opt/anaconda3/envs/achacha/lib/python3.6/site-packages/django/utils/datastructures.py", line 76, in __getitem__
    list_ = super().__getitem__(key)
KeyError: 'uploadfile'

During handling of the above exception, another exception occurred:

Traceback (most recent call last):
  File "/Users/jihyun/opt/anaconda3/envs/achacha/lib/python3.6/site-packages/django/core/handlers/exception.py", line 47, in inner
    response = get_response(request)
  File "/Users/jihyun/opt/anaconda3/envs/achacha/lib/python3.6/site-packages/django/core/handlers/base.py", line 181, in _get_response
    response = wrapped_callback(request, *callback_args, **callback_kwargs)
  File "/Users/jihyun/PJT_ACHACHA/ACHACHA_PROJECT/achacha_django/fast_search/views.py", line 59, in uploaded_image
    image = request.FILES['uploadfile'] # 업로드 된 이미지 가져오기
  File "/Users/jihyun/opt/anaconda3/envs/achacha/lib/python3.6/site-packages/django/utils/datastructures.py", line 78, in __getitem__
    raise MultiValueDictKeyError(key)
django.utils.datastructures.MultiValueDictKeyError: 'uploadfile'
[28Sep2022 00:57:13 ERROR [django.server:161] "POST /fast_search/image/upload/ HTTP/1.1" 500 74728
[28Sep2022 00:57:16 INFO [django.server:161] "GET /static/bootstrap/vendor/bootstrap/js/bootstrap.bundle.min.js.map HTTP/1.1" 200 316181
[28Sep2022 00:57:38 ERROR [django.request:230] Internal Server Error: /fast_search/image/upload/
Traceback (most recent call last):
  File "/Users/jihyun/opt/anaconda3/envs/achacha/lib/python3.6/site-packages/django/template/base.py", line 470, in parse
    compile_func = self.tags[command]
KeyError: 'endif'

During handling of the above exception, another exception occurred:

Traceback (most recent call last):
  File "/Users/jihyun/opt/anaconda3/envs/achacha/lib/python3.6/site-packages/django/core/handlers/exception.py", line 47, in inner
    response = get_response(request)
  File "/Users/jihyun/opt/anaconda3/envs/achacha/lib/python3.6/site-packages/django/core/handlers/base.py", line 181, in _get_response
    response = wrapped_callback(request, *callback_args, **callback_kwargs)
  File "/Users/jihyun/PJT_ACHACHA/ACHACHA_PROJECT/achacha_django/fast_search/views.py", line 147, in uploaded_image
    return render(request, 'fast_search/2-1_result.html', context)
  File "/Users/jihyun/opt/anaconda3/envs/achacha/lib/python3.6/site-packages/django/shortcuts.py", line 19, in render
    content = loader.render_to_string(template_name, context, request, using=using)
  File "/Users/jihyun/opt/anaconda3/envs/achacha/lib/python3.6/site-packages/django/template/loader.py", line 61, in render_to_string
    template = get_template(template_name, using=using)
  File "/Users/jihyun/opt/anaconda3/envs/achacha/lib/python3.6/site-packages/django/template/loader.py", line 15, in get_template
    return engine.get_template(template_name)
  File "/Users/jihyun/opt/anaconda3/envs/achacha/lib/python3.6/site-packages/django/template/backends/django.py", line 34, in get_template
    return Template(self.engine.get_template(template_name), self)
  File "/Users/jihyun/opt/anaconda3/envs/achacha/lib/python3.6/site-packages/django/template/engine.py", line 143, in get_template
    template, origin = self.find_template(template_name)
  File "/Users/jihyun/opt/anaconda3/envs/achacha/lib/python3.6/site-packages/django/template/engine.py", line 125, in find_template
    template = loader.get_template(name, skip=skip)
  File "/Users/jihyun/opt/anaconda3/envs/achacha/lib/python3.6/site-packages/django/template/loaders/base.py", line 30, in get_template
    contents, origin, origin.template_name, self.engine,
  File "/Users/jihyun/opt/anaconda3/envs/achacha/lib/python3.6/site-packages/django/template/base.py", line 155, in __init__
    self.nodelist = self.compile_nodelist()
  File "/Users/jihyun/opt/anaconda3/envs/achacha/lib/python3.6/site-packages/django/template/base.py", line 193, in compile_nodelist
    return parser.parse()
  File "/Users/jihyun/opt/anaconda3/envs/achacha/lib/python3.6/site-packages/django/template/base.py", line 478, in parse
    raise self.error(token, e)
  File "/Users/jihyun/opt/anaconda3/envs/achacha/lib/python3.6/site-packages/django/template/base.py", line 476, in parse
    compiled_result = compile_func(self, token)
  File "/Users/jihyun/opt/anaconda3/envs/achacha/lib/python3.6/site-packages/django/template/loader_tags.py", line 278, in do_extends
    nodelist = parser.parse()
  File "/Users/jihyun/opt/anaconda3/envs/achacha/lib/python3.6/site-packages/django/template/base.py", line 478, in parse
    raise self.error(token, e)
  File "/Users/jihyun/opt/anaconda3/envs/achacha/lib/python3.6/site-packages/django/template/base.py", line 476, in parse
    compiled_result = compile_func(self, token)
  File "/Users/jihyun/opt/anaconda3/envs/achacha/lib/python3.6/site-packages/django/template/loader_tags.py", line 216, in do_block
    nodelist = parser.parse(('endblock',))
  File "/Users/jihyun/opt/anaconda3/envs/achacha/lib/python3.6/site-packages/django/template/base.py", line 472, in parse
    self.invalid_block_tag(token, command, parse_until)
  File "/Users/jihyun/opt/anaconda3/envs/achacha/lib/python3.6/site-packages/django/template/base.py", line 528, in invalid_block_tag
    get_text_list(["'%s'" % p for p in parse_until], 'or'),
django.template.exceptions.TemplateSyntaxError: Invalid block tag on line 100: 'endif', expected 'endblock'. Did you forget to register or load this tag?
[28Sep2022 00:57:38 ERROR [django.server:161] "POST /fast_search/image/upload/ HTTP/1.1" 500 200458
[28Sep2022 00:59:59 INFO [django.server:161] "GET /fast_search/image/ HTTP/1.1" 200 21430
[28Sep2022 00:59:59 INFO [django.server:161] "GET /static/bootstrap/vendor/bootstrap/js/bootstrap.bundle.min.js.map HTTP/1.1" 200 316181
[28Sep2022 01:00:39 INFO [django.server:161] "POST /fast_search/image/upload/ HTTP/1.1" 200 17292
[28Sep2022 01:00:39 INFO [django.server:161] "GET /static/bootstrap/vendor/fontawesome-free/css/all.min.css HTTP/1.1" 304 0
[28Sep2022 01:00:39 INFO [django.server:161] "GET /static/bootstrap/css/sb-admin-2.min.css HTTP/1.1" 304 0
[28Sep2022 01:00:39 INFO [django.server:161] "GET /static/bootstrap/vendor/jquery/jquery.min.js HTTP/1.1" 304 0
[28Sep2022 01:00:39 INFO [django.server:161] "GET /static/bootstrap/vendor/bootstrap/js/bootstrap.bundle.min.js HTTP/1.1" 304 0
[28Sep2022 01:00:39 INFO [django.server:161] "GET /static/bootstrap/vendor/jquery-easing/jquery.easing.min.js HTTP/1.1" 304 0
[28Sep2022 01:00:39 INFO [django.server:161] "GET /static/bootstrap/js/sb-admin-2.js HTTP/1.1" 304 0
[28Sep2022 01:00:39 INFO [django.server:161] "GET /static/bootstrap/vendor/chart.js/Chart.min.js HTTP/1.1" 304 0
[28Sep2022 01:00:39 INFO [django.server:161] "GET /static/bootstrap/js/demo/chart-area-demo.js HTTP/1.1" 304 0
[28Sep2022 01:00:39 INFO [django.server:161] "GET /static/bootstrap/js/demo/chart-pie-demo.js HTTP/1.1" 304 0
[28Sep2022 01:00:39 INFO [django.server:161] "GET /static/bootstrap/img/logo_blue.png HTTP/1.1" 304 0
[28Sep2022 01:00:39 INFO [django.server:161] "GET /static/bootstrap/img/undraw_profile.svg HTTP/1.1" 304 0
[28Sep2022 01:00:39 INFO [django.server:161] "GET /static/bootstrap/vendor/fontawesome-free/webfonts/fa-solid-900.woff2 HTTP/1.1" 304 0
[28Sep2022 01:00:39 INFO [django.server:161] "GET /static/bootstrap/vendor/bootstrap/js/bootstrap.bundle.min.js.map HTTP/1.1" 200 316181
[28Sep2022 01:01:59 INFO [django.utils.autoreload:251] /Users/jihyun/PJT_ACHACHA/ACHACHA_PROJECT/achacha_django/fast_search/views.py changed, reloading.
[28Sep2022 01:02:01 INFO [django.utils.autoreload:637] Watching for file changes with StatReloader
[28Sep2022 01:02:04 INFO [django.utils.autoreload:251] /Users/jihyun/PJT_ACHACHA/ACHACHA_PROJECT/achacha_django/fast_search/views.py changed, reloading.
[28Sep2022 01:02:04 INFO [django.utils.autoreload:637] Watching for file changes with StatReloader
[28Sep2022 01:02:07 INFO [django.server:161] "GET / HTTP/1.1" 200 23411
[28Sep2022 01:02:08 INFO [django.server:161] "GET /static/bootstrap/img/by.jpg HTTP/1.1" 304 0
[28Sep2022 01:02:11 INFO [django.server:161] "GET /fast_search/image/ HTTP/1.1" 200 21430
[28Sep2022 01:02:11 INFO [django.server:161] "GET /static/bootstrap/vendor/bootstrap/js/bootstrap.bundle.min.js.map HTTP/1.1" 200 316181
[28Sep2022 01:02:42 INFO [django.server:161] "POST /fast_search/image/upload/ HTTP/1.1" 200 17292
[28Sep2022 01:02:42 INFO [django.server:161] "GET /static/acha_money/css/base.css HTTP/1.1" 304 0
[28Sep2022 01:02:42 INFO [django.server:161] "GET /static/bootstrap/vendor/bootstrap/js/bootstrap.bundle.min.js.map HTTP/1.1" 200 316181
[28Sep2022 01:03:07 INFO [django.utils.autoreload:251] /Users/jihyun/PJT_ACHACHA/ACHACHA_PROJECT/achacha_django/fast_search/views.py changed, reloading.
[28Sep2022 01:03:08 INFO [django.utils.autoreload:637] Watching for file changes with StatReloader
[28Sep2022 01:03:11 INFO [django.server:161] "GET /fast_search/image/ HTTP/1.1" 200 21430
[28Sep2022 01:03:12 INFO [django.server:161] "GET /static/bootstrap/vendor/bootstrap/js/bootstrap.bundle.min.js.map HTTP/1.1" 200 316181
[28Sep2022 01:03:39 INFO [django.server:161] "POST /fast_search/image/upload/ HTTP/1.1" 200 17292
[28Sep2022 01:03:39 INFO [django.server:161] "GET /static/bootstrap/vendor/bootstrap/js/bootstrap.bundle.min.js.map HTTP/1.1" 200 316181
[28Sep2022 01:07:48 INFO [django.utils.autoreload:251] /Users/jihyun/PJT_ACHACHA/ACHACHA_PROJECT/achacha_django/fast_search/views.py changed, reloading.
[28Sep2022 01:07:50 INFO [django.utils.autoreload:637] Watching for file changes with StatReloader
[28Sep2022 01:07:53 INFO [django.utils.autoreload:251] /Users/jihyun/PJT_ACHACHA/ACHACHA_PROJECT/achacha_django/fast_search/views.py changed, reloading.
[28Sep2022 01:07:54 INFO [django.utils.autoreload:637] Watching for file changes with StatReloader
[28Sep2022 01:09:26 INFO [django.server:161] "GET /fast_search/image/ HTTP/1.1" 200 21430
[28Sep2022 01:09:26 INFO [django.server:161] "GET /static/bootstrap/vendor/bootstrap/js/bootstrap.bundle.min.js.map HTTP/1.1" 200 316181
[28Sep2022 01:09:40 ERROR [django.request:230] Internal Server Error: /fast_search/image/upload/
Traceback (most recent call last):
  File "/Users/jihyun/opt/anaconda3/envs/achacha/lib/python3.6/site-packages/django/core/handlers/exception.py", line 47, in inner
    response = get_response(request)
  File "/Users/jihyun/opt/anaconda3/envs/achacha/lib/python3.6/site-packages/django/core/handlers/base.py", line 181, in _get_response
    response = wrapped_callback(request, *callback_args, **callback_kwargs)
  File "/Users/jihyun/PJT_ACHACHA/ACHACHA_PROJECT/achacha_django/fast_search/views.py", line 113, in uploaded_image
    b = list(chain(image2, lost_item_data2))
UnboundLocalError: local variable 'list' referenced before assignment
[28Sep2022 01:09:40 ERROR [django.server:161] "POST /fast_search/image/upload/ HTTP/1.1" 500 84784
[28Sep2022 04:43:55 INFO [django.server:161] "GET / HTTP/1.1" 200 23411
[28Sep2022 04:43:55 INFO [django.server:161] "GET /static/bootstrap/css/sb-admin-2.min.css HTTP/1.1" 304 0
[28Sep2022 04:43:55 INFO [django.server:161] "GET /static/bootstrap/vendor/fontawesome-free/css/all.min.css HTTP/1.1" 304 0
[28Sep2022 04:43:55 INFO [django.server:161] "GET /static/bootstrap/vendor/jquery/jquery.min.js HTTP/1.1" 304 0
[28Sep2022 04:43:55 INFO [django.server:161] "GET /static/bootstrap/vendor/bootstrap/js/bootstrap.bundle.min.js HTTP/1.1" 304 0
[28Sep2022 04:43:55 INFO [django.server:161] "GET /static/bootstrap/vendor/jquery-easing/jquery.easing.min.js HTTP/1.1" 304 0
[28Sep2022 04:43:55 INFO [django.server:161] "GET /static/bootstrap/vendor/chart.js/Chart.min.js HTTP/1.1" 304 0
[28Sep2022 04:43:55 INFO [django.server:161] "GET /static/bootstrap/js/demo/chart-area-demo.js HTTP/1.1" 304 0
[28Sep2022 04:43:55 INFO [django.server:161] "GET /static/bootstrap/js/demo/chart-pie-demo.js HTTP/1.1" 304 0
[28Sep2022 04:43:55 INFO [django.server:161] "GET /static/bootstrap/img/logo_blue.png HTTP/1.1" 304 0
[28Sep2022 04:43:55 INFO [django.server:161] "GET /static/bootstrap/img/undraw_profile.svg HTTP/1.1" 304 0
[28Sep2022 04:43:55 INFO [django.server:161] "GET /static/bootstrap/js/sb-admin-2.js HTTP/1.1" 304 0
[28Sep2022 04:43:55 INFO [django.server:161] "GET /static/bootstrap/vendor/fontawesome-free/webfonts/fa-solid-900.woff2 HTTP/1.1" 304 0
[28Sep2022 04:43:56 INFO [django.server:161] "GET /static/bootstrap/img/by.jpg HTTP/1.1" 304 0
[28Sep2022 04:45:52 INFO [django.server:161] "GET / HTTP/1.1" 200 23411
[28Sep2022 04:46:00 INFO [django.server:161] "GET /fast_search/image/ HTTP/1.1" 200 21430
[28Sep2022 04:46:00 INFO [django.server:161] "GET /static/bootstrap/vendor/bootstrap/js/bootstrap.bundle.min.js.map HTTP/1.1" 200 316181
[28Sep2022 04:46:15 ERROR [django.request:230] Internal Server Error: /fast_search/image/upload/
Traceback (most recent call last):
  File "/Users/jihyun/opt/anaconda3/envs/achacha/lib/python3.6/site-packages/django/core/handlers/exception.py", line 47, in inner
    response = get_response(request)
  File "/Users/jihyun/opt/anaconda3/envs/achacha/lib/python3.6/site-packages/django/core/handlers/base.py", line 181, in _get_response
    response = wrapped_callback(request, *callback_args, **callback_kwargs)
  File "/Users/jihyun/PJT_ACHACHA/ACHACHA_PROJECT/achacha_django/fast_search/views.py", line 113, in uploaded_image
    b = list(chain(image2, lost_item_data2))
UnboundLocalError: local variable 'list' referenced before assignment
[28Sep2022 04:46:15 ERROR [django.server:161] "POST /fast_search/image/upload/ HTTP/1.1" 500 84784
[28Sep2022 05:18:56 ERROR [django.request:230] Internal Server Error: /fast_search/image/upload/
Traceback (most recent call last):
  File "/Users/jihyun/opt/anaconda3/envs/achacha/lib/python3.6/site-packages/django/core/handlers/exception.py", line 47, in inner
    response = get_response(request)
  File "/Users/jihyun/opt/anaconda3/envs/achacha/lib/python3.6/site-packages/django/core/handlers/base.py", line 181, in _get_response
    response = wrapped_callback(request, *callback_args, **callback_kwargs)
  File "/Users/jihyun/PJT_ACHACHA/ACHACHA_PROJECT/achacha_django/fast_search/views.py", line 113, in uploaded_image
    b = list(chain(image2, lost_item_data2))
UnboundLocalError: local variable 'list' referenced before assignment
[28Sep2022 05:18:56 ERROR [django.server:161] "POST /fast_search/image/upload/ HTTP/1.1" 500 84784
[28Sep2022 06:29:26 INFO [django.utils.autoreload:251] /Users/jihyun/PJT_ACHACHA/ACHACHA_PROJECT/achacha_django/fast_search/views.py changed, reloading.
[28Sep2022 06:29:36 INFO [django.utils.autoreload:637] Watching for file changes with StatReloader
[28Sep2022 06:29:51 INFO [django.utils.autoreload:251] /Users/jihyun/PJT_ACHACHA/ACHACHA_PROJECT/achacha_django/fast_search/views.py changed, reloading.
[28Sep2022 06:29:52 INFO [django.utils.autoreload:637] Watching for file changes with StatReloader
[28Sep2022 06:29:56 INFO [django.server:161] "GET / HTTP/1.1" 200 23411
[28Sep2022 06:29:56 INFO [django.server:161] "GET /static/bootstrap/css/sb-admin-2.min.css HTTP/1.1" 304 0
[28Sep2022 06:29:56 INFO [django.server:161] "GET /static/bootstrap/vendor/fontawesome-free/css/all.min.css HTTP/1.1" 304 0
[28Sep2022 06:29:56 INFO [django.server:161] "GET /static/bootstrap/vendor/jquery/jquery.min.js HTTP/1.1" 304 0
[28Sep2022 06:29:56 INFO [django.server:161] "GET /static/bootstrap/vendor/bootstrap/js/bootstrap.bundle.min.js HTTP/1.1" 304 0
[28Sep2022 06:29:56 INFO [django.server:161] "GET /static/bootstrap/vendor/jquery-easing/jquery.easing.min.js HTTP/1.1" 304 0
[28Sep2022 06:29:56 INFO [django.server:161] "GET /static/bootstrap/js/sb-admin-2.js HTTP/1.1" 304 0
[28Sep2022 06:29:56 INFO [django.server:161] "GET /static/bootstrap/vendor/chart.js/Chart.min.js HTTP/1.1" 304 0
[28Sep2022 06:29:56 INFO [django.server:161] "GET /static/bootstrap/js/demo/chart-pie-demo.js HTTP/1.1" 304 0
[28Sep2022 06:29:56 INFO [django.server:161] "GET /static/bootstrap/img/undraw_profile.svg HTTP/1.1" 304 0
[28Sep2022 06:29:56 INFO [django.server:161] "GET /static/bootstrap/img/logo_blue.png HTTP/1.1" 304 0
[28Sep2022 06:29:56 INFO [django.server:161] "GET /static/bootstrap/js/demo/chart-area-demo.js HTTP/1.1" 304 0
[28Sep2022 06:29:56 INFO [django.server:161] "GET /static/bootstrap/vendor/fontawesome-free/webfonts/fa-solid-900.woff2 HTTP/1.1" 304 0
[28Sep2022 06:29:57 INFO [django.server:161] "GET /static/bootstrap/img/by.jpg HTTP/1.1" 304 0
[28Sep2022 06:30:04 INFO [django.server:161] "GET /fast_search/image/ HTTP/1.1" 200 21430
[28Sep2022 06:30:04 INFO [django.server:161] "GET /static/bootstrap/img/logo_blue.png HTTP/1.1" 304 0
[28Sep2022 06:30:04 INFO [django.server:161] "GET /static/bootstrap/img/undraw_profile.svg HTTP/1.1" 304 0
[28Sep2022 06:30:04 INFO [django.server:161] "GET /static/bootstrap/vendor/jquery/jquery.min.js HTTP/1.1" 304 0
[28Sep2022 06:30:04 INFO [django.server:161] "GET /static/bootstrap/vendor/bootstrap/js/bootstrap.bundle.min.js HTTP/1.1" 304 0
[28Sep2022 06:30:04 INFO [django.server:161] "GET /static/bootstrap/vendor/jquery-easing/jquery.easing.min.js HTTP/1.1" 304 0
[28Sep2022 06:30:04 INFO [django.server:161] "GET /static/bootstrap/js/sb-admin-2.js HTTP/1.1" 304 0
[28Sep2022 06:30:04 INFO [django.server:161] "GET /static/bootstrap/vendor/chart.js/Chart.min.js HTTP/1.1" 304 0
[28Sep2022 06:30:04 INFO [django.server:161] "GET /static/bootstrap/js/demo/chart-area-demo.js HTTP/1.1" 304 0
[28Sep2022 06:30:04 INFO [django.server:161] "GET /static/bootstrap/js/demo/chart-pie-demo.js HTTP/1.1" 304 0
[28Sep2022 06:30:04 INFO [django.server:161] "GET /static/bootstrap/vendor/fontawesome-free/webfonts/fa-solid-900.woff2 HTTP/1.1" 304 0
[28Sep2022 06:30:07 INFO [django.server:161] "GET /static/bootstrap/vendor/bootstrap/js/bootstrap.bundle.min.js.map HTTP/1.1" 200 316181
[28Sep2022 06:30:42 INFO [django.server:161] "POST /fast_search/image/upload/ HTTP/1.1" 200 19014
[28Sep2022 06:30:42 INFO [django.server:161] "GET /static/acha_money/css/base.css HTTP/1.1" 304 0
[28Sep2022 06:30:42 WARNING [django.request:230] Not Found: /fast_search/image/upload/media/result_image/F2022041200000158-1.jpg
[28Sep2022 06:30:42 WARNING [django.request:230] Not Found: /fast_search/image/upload/media/result_image/F2022042800001472-1.jpg
[28Sep2022 06:30:42 WARNING [django.request:230] Not Found: /fast_search/image/upload/media/result_image/F2022040300000364-1.jpg
[28Sep2022 06:30:42 WARNING [django.request:230] Not Found: /fast_search/image/upload/media/result_image/F2022042500002724-1.jpg
[28Sep2022 06:30:42 WARNING [django.server:161] "GET /fast_search/image/upload/media/result_image/F2022041200000158-1.jpg HTTP/1.1" 404 4603
[28Sep2022 06:30:42 WARNING [django.server:161] "GET /fast_search/image/upload/media/result_image/F2022042800001472-1.jpg HTTP/1.1" 404 4603
[28Sep2022 06:30:42 WARNING [django.server:161] "GET /fast_search/image/upload/media/result_image/F2022042500002724-1.jpg HTTP/1.1" 404 4603
[28Sep2022 06:30:42 WARNING [django.server:161] "GET /fast_search/image/upload/media/result_image/F2022040300000364-1.jpg HTTP/1.1" 404 4603
[28Sep2022 06:30:42 WARNING [django.request:230] Not Found: /fast_search/image/upload/media/result_image/F2022032700001651-1.jpg
[28Sep2022 06:30:42 WARNING [django.server:161] "GET /fast_search/image/upload/media/result_image/F2022032700001651-1.jpg HTTP/1.1" 404 4603
[28Sep2022 06:30:42 WARNING [django.request:230] Not Found: /fast_search/image/upload/media/result_image/F2022040400003538-1.jpg
[28Sep2022 06:30:42 WARNING [django.server:161] "GET /fast_search/image/upload/media/result_image/F2022040400003538-1.jpg HTTP/1.1" 404 4603
[28Sep2022 06:30:42 INFO [django.server:161] "GET /static/bootstrap/vendor/bootstrap/js/bootstrap.bundle.min.js.map HTTP/1.1" 200 316181
[28Sep2022 06:32:31 INFO [django.utils.autoreload:251] /Users/jihyun/PJT_ACHACHA/ACHACHA_PROJECT/achacha_django/fast_search/views.py changed, reloading.
[28Sep2022 06:32:32 INFO [django.utils.autoreload:637] Watching for file changes with StatReloader
[28Sep2022 06:36:36 INFO [django.utils.autoreload:251] /Users/jihyun/PJT_ACHACHA/ACHACHA_PROJECT/achacha_django/fast_search/views.py changed, reloading.
[28Sep2022 06:36:38 INFO [django.utils.autoreload:637] Watching for file changes with StatReloader
[28Sep2022 06:40:41 INFO [django.utils.autoreload:251] /Users/jihyun/PJT_ACHACHA/ACHACHA_PROJECT/achacha_django/fast_search/views.py changed, reloading.
[28Sep2022 06:40:43 INFO [django.utils.autoreload:637] Watching for file changes with StatReloader
[28Sep2022 06:42:19 INFO [django.utils.autoreload:251] /Users/jihyun/PJT_ACHACHA/ACHACHA_PROJECT/achacha_django/fast_search/views.py changed, reloading.
[28Sep2022 06:42:21 INFO [django.utils.autoreload:637] Watching for file changes with StatReloader
